<?xml version="1.0" ?>

<sdf version="1.8">
  <world name="empty_world">

    <!-- Lighting conditions -->
    <light name="sun" type="directional">
      <cast_shadows>true</cast_shadows>
      <pose>0 0 10 0 0 0</pose>
      <diffuse>0.8 0.8 0.8 1</diffuse>
      <specular>0.2 0.2 0.2 1</specular>
      <attenuation>
        <range>1000</range>
        <constant>0.9</constant>
        <linear>0.01</linear>
        <quadratic>0.001</quadratic>
      </attenuation>
      <direction>-0.5 0.1 -0.9</direction>
    </light>

    <!-- Ground plane -->
    <model name="ground_plane">
      <static>true</static>
      <link name="link">
        <collision name="collision">
          <geometry>
            <plane>
              <normal>0 0 1</normal>
              <size>100 100</size>
            </plane>
          </geometry>
        </collision>
        <visual name="visual">
          <geometry>
            <plane>
              <normal>0 0 1</normal>
              <size>100 100</size>
            </plane>
          </geometry>
          <material>
            <ambient>0.8 0.8 0.8 1</ambient>
            <diffuse>0.8 0.8 0.8 1</diffuse>
            <specular>0.8 0.8 0.8 1</specular>
          </material>
        </visual>
      </link>
    </model>

    <!-- Conveyor belts -->
    <model name="conveyor_belt_0">
        <pose>1.980528 -1.256258 0 0 0 1.57</pose>
        <model name="conveyorbelt_fixed_0">          
            <static>true</static>
            <link name="belt_visual">
                <visual name="visual">
                    <geometry>
                        <mesh>
                            <scale>1 1 1</scale>
                            <uri>model://conveyor_belt/meshes/conveyor_belt.dae</uri>
                        </mesh>
                    </geometry>
                </visual>
                <collision name="collision">
                    <origin xyz="0 0 0" rpy="0.0 0.0 0.0"/>
                    <geometry>
                        <mesh>
                            <scale>1 1 1</scale>
                            <uri>model://conveyor_belt/meshes/conveyor_belt.dae</uri>
                        </mesh>
                    </geometry>
                </collision>
            </link>
        </model>

        <model name="conveyorbelt_moving_0">
            <allow_auto_disable>0</allow_auto_disable>
            <static>false</static>
            <pose>0 0 0.741 0 0 0.0</pose>
            <link name="belt_moving">
                <inertial>
                    <mass>100.0</mass>
                    <inertia>
                        <ixx>0.0</ixx>
                        <ixy>0.0</ixy>
                        <ixz>0.0</ixz>
                        <iyy>0.0</iyy>
                        <iyz>0.0</iyz>
                        <izz>0.0</izz>
                    </inertia>
                </inertial>
                <collision name="belt_collision">
                    <geometry>
                        <box>
                            <size>0.425 1.2 0.00001</size>
                        </box>
                    </geometry>
                    <surface>
                        <friction>
                            <ode>
                                <mu>100.0</mu>
                                <mu2>100.0</mu2>
                            </ode>
                            <torsional>
                                <coefficient>1000.0</coefficient>
                                <patch_radius>0.1</patch_radius>
                            </torsional>
                        </friction>
                    </surface>
                </collision>
            </link>
        </model>
        <joint name="belt_joint" type="prismatic">
            <parent>conveyorbelt_fixed_0::belt_visual</parent>
            <child>conveyorbelt_moving_0::belt_moving</child>
            <axis>
                <xyz>0 1 0</xyz>
                <limit>
                    <lower>0.0</lower>
                    <upper>0.01</upper>
                </limit>
            </axis>
        </joint>
    </model>

    <model name="conveyor_belt_1">
        <pose>0.782638 -1.263266 0 0 0 1.57</pose>
        <model name="conveyorbelt_fixed_1">          
            <static>true</static>
            <link name="belt_visual">
                <visual name="visual">
                    <geometry>
                        <mesh>
                            <scale>1 1 1</scale>
                            <uri>model://conveyor_belt/meshes/conveyor_belt.dae</uri>
                        </mesh>
                    </geometry>
                </visual>
                <collision name="collision">
                    <origin xyz="0 0 0" rpy="0.0 0.0 0.0"/>
                    <geometry>
                        <mesh>
                            <scale>1 1 1</scale>
                            <uri>model://conveyor_belt/meshes/conveyor_belt.dae</uri>
                        </mesh>
                    </geometry>
                </collision>
            </link>
        </model>
        <model name="conveyorbelt_moving_1">
            <allow_auto_disable>0</allow_auto_disable>
            <static>false</static>
            <pose>0 0 0.741 0 0 0.0</pose>
            <link name="belt_moving">
                <inertial>
                    <mass>100.0</mass>
                    <inertia>
                        <ixx>0.0</ixx>
                        <ixy>0.0</ixy>
                        <ixz>0.0</ixz>
                        <iyy>0.0</iyy>
                        <iyz>0.0</iyz>
                        <izz>0.0</izz>
                    </inertia>
                </inertial>
                <collision name="belt_collision">
                    <geometry>
                        <box>
                            <size>0.425 1.2 0.00001</size>
                        </box>
                    </geometry>
                    <surface>
                        <friction>
                            <ode>
                                <mu>100.0</mu>
                                <mu2>100.0</mu2>
                            </ode>
                            <torsional>
                                <coefficient>1000.0</coefficient>
                                <patch_radius>0.1</patch_radius>
                            </torsional>
                        </friction>
                    </surface>
                </collision>
            </link>
        </model>
        <joint name="belt_joint" type="prismatic">
            <parent>conveyorbelt_fixed_1::belt_visual</parent>
            <child>conveyorbelt_moving_1::belt_moving</child>
            <axis>
                <xyz>0 1 0</xyz>
                <limit>
                    <lower>0.0</lower>
                    <upper>0.01</upper>
                </limit>
            </axis>
        </joint>

    </model>

    <model name="conveyor_belt_2">
        <pose>-0.415252 -1.263266 0 0 0 1.57</pose>
        <model name="conveyorbelt_fixed_2">          
            <static>true</static>
            <link name="belt_visual">
                <visual name="visual">
                    <geometry>
                        <mesh>
                            <scale>1 1 1</scale>
                            <uri>model://conveyor_belt/meshes/conveyor_belt.dae</uri>
                        </mesh>
                    </geometry>
                </visual>
                <collision name="collision">
                    <origin xyz="0 0 0" rpy="0.0 0.0 0.0"/>
                    <geometry>
                        <mesh>
                            <scale>1 1 1</scale>
                            <uri>model://conveyor_belt/meshes/conveyor_belt.dae</uri>
                        </mesh>
                    </geometry>
                </collision>
            </link>
        </model>
        <model name="conveyorbelt_moving_2">
            <allow_auto_disable>0</allow_auto_disable>
            <static>false</static>
            <pose>0 0 0.741 0 0 0.0</pose>
            <link name="belt_moving">
                <inertial>
                    <mass>100.0</mass>
                    <inertia>
                        <ixx>0.0</ixx>
                        <ixy>0.0</ixy>
                        <ixz>0.0</ixz>
                        <iyy>0.0</iyy>
                        <iyz>0.0</iyz>
                        <izz>0.0</izz>
                    </inertia>
                </inertial>
                <collision name="belt_collision">
                    <geometry>
                        <box>
                            <size>0.425 1.2 0.00001</size>
                        </box>
                    </geometry>
                    <surface>
                        <friction>
                            <ode>
                                <mu>100.0</mu>
                                <mu2>100.0</mu2>
                            </ode>
                            <torsional>
                                <coefficient>1000.0</coefficient>
                                <patch_radius>0.1</patch_radius>
                            </torsional>
                        </friction>
                    </surface>
                </collision>
            </link>
        </model>
        <joint name="belt_joint" type="prismatic">
            <parent>conveyorbelt_fixed_2::belt_visual</parent>
            <child>conveyorbelt_moving_2::belt_moving</child>
            <axis>
                <xyz>0 1 0</xyz>
                <limit>
                    <lower>0.0</lower>
                    <upper>0.01</upper>
                </limit>
            </axis>
        </joint>

    </model>

    <model name="conveyor_belt_3">
        <pose>-1.613142 -1.263266 0 0 0 1.57</pose>
        <model name="conveyorbelt_fixed_3">          
            <static>true</static>
            <link name="belt_visual">
                <visual name="visual">
                    <geometry>
                        <mesh>
                            <scale>1 1 1</scale>
                            <uri>model://conveyor_belt/meshes/conveyor_belt.dae</uri>
                        </mesh>
                    </geometry>
                </visual>
                <collision name="collision">
                    <origin xyz="0 0 0" rpy="0.0 0.0 0.0"/>
                    <geometry>
                        <mesh>
                            <scale>1 1 1</scale>
                            <uri>model://conveyor_belt/meshes/conveyor_belt.dae</uri>
                        </mesh>
                    </geometry>
                </collision>
            </link>
        </model>
        <model name="conveyorbelt_moving_3">
            <allow_auto_disable>0</allow_auto_disable>
            <static>false</static>
            <pose>0 0 0.741 0 0 0.0</pose>
            <link name="belt_moving">
                <inertial>
                    <mass>100.0</mass>
                    <inertia>
                        <ixx>0.0</ixx>
                        <ixy>0.0</ixy>
                        <ixz>0.0</ixz>
                        <iyy>0.0</iyy>
                        <iyz>0.0</iyz>
                        <izz>0.0</izz>
                    </inertia>
                </inertial>
                <collision name="belt_collision">
                    <geometry>
                        <box>
                            <size>0.425 1.2 0.00001</size>
                        </box>
                    </geometry>
                    <surface>
                        <friction>
                            <ode>
                                <mu>100.0</mu>
                                <mu2>100.0</mu2>
                            </ode>
                            <torsional>
                                <coefficient>1000.0</coefficient>
                                <patch_radius>0.1</patch_radius>
                            </torsional>
                        </friction>
                    </surface>
                </collision>
            </link>
        </model>
        <joint name="belt_joint" type="prismatic">
            <parent>conveyorbelt_fixed_3::belt_visual</parent>
            <child>conveyorbelt_moving_3::belt_moving</child>
            <axis>
                <xyz>0 1 0</xyz>
                <limit>
                    <lower>0.0</lower>
                    <upper>0.01</upper>
                </limit>
            </axis>
        </joint>

    </model>

    <model name="conveyor_belt_4">
        <pose>3.185631 -1.263266 0 0 0 1.57</pose>
        <model name="conveyorbelt_fixed_4">          
            <static>true</static>
            <link name="belt_visual">
                <visual name="visual">
                    <geometry>
                        <mesh>
                            <scale>1 1 1</scale>
                            <uri>model://conveyor_belt/meshes/conveyor_belt.dae</uri>
                        </mesh>
                    </geometry>
                </visual>
                <collision name="collision">
                    <origin xyz="0 0 0" rpy="0.0 0.0 0.0"/>
                    <geometry>
                        <mesh>
                            <scale>1 1 1</scale>
                            <uri>model://conveyor_belt/meshes/conveyor_belt.dae</uri>
                        </mesh>
                    </geometry>
                </collision>
            </link>
        </model>
        <model name="conveyorbelt_moving_4">
            <allow_auto_disable>0</allow_auto_disable>
            <static>false</static>
            <pose>0 0 0.741 0 0 0.0</pose>
            <link name="belt_moving">
                <inertial>
                    <mass>100.0</mass>
                    <inertia>
                        <ixx>0.0</ixx>
                        <ixy>0.0</ixy>
                        <ixz>0.0</ixz>
                        <iyy>0.0</iyy>
                        <iyz>0.0</iyz>
                        <izz>0.0</izz>
                    </inertia>
                </inertial>
                <collision name="belt_collision">
                    <geometry>
                        <box>
                            <size>0.425 1.2 0.00001</size>
                        </box>
                    </geometry>
                    <surface>
                        <friction>
                            <ode>
                                <mu>100.0</mu>
                                <mu2>100.0</mu2>
                            </ode>
                            <torsional>
                                <coefficient>1000.0</coefficient>
                                <patch_radius>0.1</patch_radius>
                            </torsional>
                        </friction>
                    </surface>
                </collision>
            </link>
        </model>
        <joint name="belt_joint" type="prismatic">
            <parent>conveyorbelt_fixed_4::belt_visual</parent>
            <child>conveyorbelt_moving_4::belt_moving</child>
            <axis>
                <xyz>0 1 0</xyz>
                <limit>
                    <lower>0.0</lower>
                    <upper>0.01</upper>
                </limit>
            </axis>
        </joint>

    </model>

    <model name="conveyor_belt_5">
        <pose>4.383521 -1.263266 0 0 0 1.57</pose>
        <model name="conveyorbelt_fixed_5">          
            <static>true</static>
            <link name="belt_visual">
                <visual name="visual">
                    <geometry>
                        <mesh>
                            <scale>1 1 1</scale>
                            <uri>model://conveyor_belt/meshes/conveyor_belt.dae</uri>
                        </mesh>
                    </geometry>
                </visual>
                <collision name="collision">
                    <origin xyz="0 0 0" rpy="0.0 0.0 0.0"/>
                    <geometry>
                        <mesh>
                            <scale>1 1 1</scale>
                            <uri>model://conveyor_belt/meshes/conveyor_belt.dae</uri>
                        </mesh>
                    </geometry>
                </collision>
            </link>
        </model>
        <model name="conveyorbelt_moving_5">
            <allow_auto_disable>0</allow_auto_disable>
            <static>false</static>
            <pose>0 0 0.741 0 0 0.0</pose>
            <link name="belt_moving">
                <inertial>
                    <mass>100.0</mass>
                    <inertia>
                        <ixx>0.0</ixx>
                        <ixy>0.0</ixy>
                        <ixz>0.0</ixz>
                        <iyy>0.0</iyy>
                        <iyz>0.0</iyz>
                        <izz>0.0</izz>
                    </inertia>
                </inertial>
                <collision name="belt_collision">
                    <geometry>
                        <box>
                            <size>0.425 1.2 0.00001</size>
                        </box>
                    </geometry>
                    <surface>
                        <friction>
                            <ode>
                                <mu>100.0</mu>
                                <mu2>100.0</mu2>
                            </ode>
                            <torsional>
                                <coefficient>1000.0</coefficient>
                                <patch_radius>0.1</patch_radius>
                            </torsional>
                        </friction>
                    </surface>
                </collision>
            </link>
        </model>
        <joint name="belt_joint" type="prismatic">
            <parent>conveyorbelt_fixed_5::belt_visual</parent>
            <child>conveyorbelt_moving_5::belt_moving</child>
            <axis>
                <xyz>0 1 0</xyz>
                <limit>
                    <lower>0.0</lower>
                    <upper>0.01</upper>
                </limit>
            </axis>
        </joint>
    </model>

    <model name="conveyor_belt_6">
        <pose>-3.989316 -1.260457 0 0 0 1.57</pose>
        <model name="conveyorbelt_fixed_6">          
            <static>true</static>
            <link name="belt_visual">
                <visual name="visual">
                    <geometry>
                        <mesh>
                            <scale>1 1 1</scale>
                            <uri>model://conveyor_belt/meshes/conveyor_belt.dae</uri>
                        </mesh>
                    </geometry>
                </visual>
                <collision name="collision">
                    <origin xyz="0 0 0" rpy="0.0 0.0 0.0"/>
                    <geometry>
                        <mesh>
                            <scale>1 1 1</scale>
                            <uri>model://conveyor_belt/meshes/conveyor_belt.dae</uri>
                        </mesh>
                    </geometry>
                </collision>
            </link>
        </model>
        <model name="conveyorbelt_moving_6">
            <allow_auto_disable>0</allow_auto_disable>
            <static>false</static>
            <pose>0 0 0.741 0 0 0.0</pose>
            <link name="belt_moving">
                <inertial>
                    <mass>100.0</mass>
                    <inertia>
                        <ixx>0.0</ixx>
                        <ixy>0.0</ixy>
                        <ixz>0.0</ixz>
                        <iyy>0.0</iyy>
                        <iyz>0.0</iyz>
                        <izz>0.0</izz>
                    </inertia>
                </inertial>
                <collision name="belt_collision">
                    <geometry>
                        <box>
                            <size>0.425 1.2 0.00001</size>
                        </box>
                    </geometry>
                    <surface>
                        <friction>
                            <ode>
                                <mu>100.0</mu>
                                <mu2>100.0</mu2>
                            </ode>
                            <torsional>
                                <coefficient>1000.0</coefficient>
                                <patch_radius>0.1</patch_radius>
                            </torsional>
                        </friction>
                    </surface>
                </collision>
            </link>
        </model>
        <joint name="belt_joint" type="prismatic">
            <parent>conveyorbelt_fixed_6::belt_visual</parent>
            <child>conveyorbelt_moving_6::belt_moving</child>
            <axis>
                <xyz>0 1 0</xyz>
                <limit>
                    <lower>0.0</lower>
                    <upper>0.01</upper>
                </limit>
            </axis>
        </joint>

    </model>

    <model name="conveyor_belt_7">
        <pose>-5.182224 -1.260457 0 0 0 1.57</pose>
        <model name="conveyorbelt_fixed_7">          
            <static>true</static>
            <link name="belt_visual">
                <visual name="visual">
                    <geometry>
                        <mesh>
                            <scale>1 1 1</scale>
                            <uri>model://conveyor_belt/meshes/conveyor_belt.dae</uri>
                        </mesh>
                    </geometry>
                </visual>
                <collision name="collision">
                    <origin xyz="0 0 0" rpy="0.0 0.0 0.0"/>
                    <geometry>
                        <mesh>
                            <scale>1 1 1</scale>
                            <uri>model://conveyor_belt/meshes/conveyor_belt.dae</uri>
                        </mesh>
                    </geometry>
                </collision>
            </link>
        </model>
        <model name="conveyorbelt_moving_7">
            <allow_auto_disable>0</allow_auto_disable>
            <static>false</static>
            <pose>0 0 0.741 0 0 0.0</pose>
            <link name="belt_moving">
                <inertial>
                    <mass>100.0</mass>
                    <inertia>
                        <ixx>0.0</ixx>
                        <ixy>0.0</ixy>
                        <ixz>0.0</ixz>
                        <iyy>0.0</iyy>
                        <iyz>0.0</iyz>
                        <izz>0.0</izz>
                    </inertia>
                </inertial>
                <collision name="belt_collision">
                    <geometry>
                        <box>
                            <size>0.425 1.2 0.00001</size>
                        </box>
                    </geometry>
                    <surface>
                        <friction>
                            <ode>
                                <mu>100.0</mu>
                                <mu2>100.0</mu2>
                            </ode>
                            <torsional>
                                <coefficient>1000.0</coefficient>
                                <patch_radius>0.1</patch_radius>
                            </torsional>
                        </friction>
                    </surface>
                </collision>
            </link>
        </model>
        <joint name="belt_joint" type="prismatic">
            <parent>conveyorbelt_fixed_7::belt_visual</parent>
            <child>conveyorbelt_moving_7::belt_moving</child>
            <axis>
                <xyz>0 1 0</xyz>
                <limit>
                    <lower>0.0</lower>
                    <upper>0.01</upper>
                </limit>
            </axis>
        </joint>

    </model>

    <model name="conveyor_belt_8">
        <pose>-6.356115 -1.258015 0 0 0 1.57</pose>
        <model name="conveyorbelt_fixed_8">          
            <static>true</static>
            <link name="belt_visual">
                <visual name="visual">
                    <geometry>
                        <mesh>
                            <scale>1 1 1</scale>
                            <uri>model://conveyor_belt/meshes/conveyor_belt.dae</uri>
                        </mesh>
                    </geometry>
                </visual>
                <collision name="collision">
                    <origin xyz="0 0 0" rpy="0.0 0.0 0.0"/>
                    <geometry>
                        <mesh>
                            <scale>1 1 1</scale>
                            <uri>model://conveyor_belt/meshes/conveyor_belt.dae</uri>
                        </mesh>
                    </geometry>
                </collision>
            </link>
        </model>
        <model name="conveyorbelt_moving_8">
            <allow_auto_disable>0</allow_auto_disable>
            <static>false</static>
            <pose>0 0 0.741 0 0 0.0</pose>
            <link name="belt_moving">
                <inertial>
                    <mass>100.0</mass>
                    <inertia>
                        <ixx>0.0</ixx>
                        <ixy>0.0</ixy>
                        <ixz>0.0</ixz>
                        <iyy>0.0</iyy>
                        <iyz>0.0</iyz>
                        <izz>0.0</izz>
                    </inertia>
                </inertial>
                <collision name="belt_collision">
                    <geometry>
                        <box>
                            <size>0.425 1.2 0.00001</size>
                        </box>
                    </geometry>
                    <surface>
                        <friction>
                            <ode>
                                <mu>100.0</mu>
                                <mu2>100.0</mu2>
                            </ode>
                            <torsional>
                                <coefficient>1000.0</coefficient>
                                <patch_radius>0.1</patch_radius>
                            </torsional>
                        </friction>
                    </surface>
                </collision>
            </link>
        </model>
        <joint name="belt_joint" type="prismatic">
            <parent>conveyorbelt_fixed_8::belt_visual</parent>
            <child>conveyorbelt_moving_8::belt_moving</child>
            <axis>
                <xyz>0 1 0</xyz>
                <limit>
                    <lower>0.0</lower>
                    <upper>0.01</upper>
                </limit>
            </axis>
        </joint>

    </model>

    <model name="conveyor_belt_9">
        <pose>-7.537606 -1.257890 0 0 0 1.57</pose>
        <model name="conveyorbelt_fixed_9">          
            <static>true</static>
            <link name="belt_visual">
                <visual name="visual">
                    <geometry>
                        <mesh>
                            <scale>1 1 1</scale>
                            <uri>model://conveyor_belt/meshes/conveyor_belt.dae</uri>
                        </mesh>
                    </geometry>
                </visual>
                <collision name="collision">
                    <origin xyz="0 0 0" rpy="0.0 0.0 0.0"/>
                    <geometry>
                        <mesh>
                            <scale>1 1 1</scale>
                            <uri>model://conveyor_belt/meshes/conveyor_belt.dae</uri>
                        </mesh>
                    </geometry>
                </collision>
            </link>
        </model>
        <model name="conveyorbelt_moving_9">
            <allow_auto_disable>0</allow_auto_disable>
            <static>false</static>
            <pose>0 0 0.741 0 0 0.0</pose>
            <link name="belt_moving">
                <inertial>
                    <mass>100.0</mass>
                    <inertia>
                        <ixx>0.0</ixx>
                        <ixy>0.0</ixy>
                        <ixz>0.0</ixz>
                        <iyy>0.0</iyy>
                        <iyz>0.0</iyz>
                        <izz>0.0</izz>
                    </inertia>
                </inertial>
                <collision name="belt_collision">
                    <geometry>
                        <box>
                            <size>0.425 1.2 0.00001</size>
                        </box>
                    </geometry>
                    <surface>
                        <friction>
                            <ode>
                                <mu>100.0</mu>
                                <mu2>100.0</mu2>
                            </ode>
                            <torsional>
                                <coefficient>1000.0</coefficient>
                                <patch_radius>0.1</patch_radius>
                            </torsional>
                        </friction>
                    </surface>
                </collision>
            </link>
        </model>
        <joint name="belt_joint" type="prismatic">
            <parent>conveyorbelt_fixed_9::belt_visual</parent>
            <child>conveyorbelt_moving_9::belt_moving</child>
            <axis>
                <xyz>0 1 0</xyz>
                <limit>
                    <lower>0.0</lower>
                    <upper>0.01</upper>
                </limit>
            </axis>
        </joint>

    </model>

    <model name="conveyor_belt_10">
        <pose>-2.799608 -1.263694 0 0 0 1.57</pose>
        <model name="conveyorbelt_fixed_10">          
            <static>true</static>
            <link name="belt_visual">
                <visual name="visual">
                    <geometry>
                        <mesh>
                            <scale>1 1 1</scale>
                            <uri>model://conveyor_belt/meshes/conveyor_belt.dae</uri>
                        </mesh>
                    </geometry>
                </visual>
                <collision name="collision">
                    <origin xyz="0 0 0" rpy="0.0 0.0 0.0"/>
                    <geometry>
                        <mesh>
                            <scale>1 1 1</scale>
                            <uri>model://conveyor_belt/meshes/conveyor_belt.dae</uri>
                        </mesh>
                    </geometry>
                </collision>
            </link>
        </model>
        <model name="conveyorbelt_moving_10">
            <allow_auto_disable>0</allow_auto_disable>
            <static>false</static>
            <pose>0 0 0.741 0 0 0.0</pose>
            <link name="belt_moving">
                <inertial>
                    <mass>100.0</mass>
                    <inertia>
                        <ixx>0.0</ixx>
                        <ixy>0.0</ixy>
                        <ixz>0.0</ixz>
                        <iyy>0.0</iyy>
                        <iyz>0.0</iyz>
                        <izz>0.0</izz>
                    </inertia>
                </inertial>
                <collision name="belt_collision">
                    <geometry>
                        <box>
                            <size>0.425 1.2 0.00001</size>
                        </box>
                    </geometry>
                    <surface>
                        <friction>
                            <ode>
                                <mu>100.0</mu>
                                <mu2>100.0</mu2>
                            </ode>
                            <torsional>
                                <coefficient>1000.0</coefficient>
                                <patch_radius>0.1</patch_radius>
                            </torsional>
                        </friction>
                    </surface>
                </collision>
            </link>
        </model>
        <joint name="belt_joint" type="prismatic">
            <parent>conveyorbelt_fixed_10::belt_visual</parent>
            <child>conveyorbelt_moving_10::belt_moving</child>
            <axis>
                <xyz>0 1 0</xyz>
                <limit>
                    <lower>0.0</lower>
                    <upper>0.01</upper>
                </limit>
            </axis>
        </joint>

    </model>
    
    <model name="conveyor_belt_11">
        <pose>5.580262 -1.267404 0 0 0 1.57</pose>
        <model name="conveyorbelt_fixed_11">          
            <static>true</static>
            <link name="belt_visual">
                <visual name="visual">
                    <geometry>
                        <mesh>
                            <scale>1 1 1</scale>
                            <uri>model://conveyor_belt/meshes/conveyor_belt.dae</uri>
                        </mesh>
                    </geometry>
                </visual>
                <collision name="collision">
                    <origin xyz="0 0 0" rpy="0.0 0.0 0.0"/>
                    <geometry>
                        <mesh>
                            <scale>1 1 1</scale>
                            <uri>model://conveyor_belt/meshes/conveyor_belt.dae</uri>
                        </mesh>
                    </geometry>
                </collision>
            </link>
        </model>
        <model name="conveyorbelt_moving_11">
            <allow_auto_disable>0</allow_auto_disable>
            <static>false</static>
            <pose>0 0 0.741 0 0 0.0</pose>
            <link name="belt_moving">
                <inertial>
                    <mass>100.0</mass>
                    <inertia>
                        <ixx>0.0</ixx>
                        <ixy>0.0</ixy>
                        <ixz>0.0</ixz>
                        <iyy>0.0</iyy>
                        <iyz>0.0</iyz>
                        <izz>0.0</izz>
                    </inertia>
                </inertial>
                <collision name="belt_collision">
                    <geometry>
                        <box>
                            <size>0.425 1.2 0.00001</size>
                        </box>
                    </geometry>
                    <surface>
                        <friction>
                            <ode>
                                <mu>100.0</mu>
                                <mu2>100.0</mu2>
                            </ode>
                            <torsional>
                                <coefficient>1000.0</coefficient>
                                <patch_radius>0.1</patch_radius>
                            </torsional>
                        </friction>
                    </surface>
                </collision>
            </link>
        </model>
        <joint name="belt_joint" type="prismatic">
            <parent>conveyorbelt_fixed_11::belt_visual</parent>
            <child>conveyorbelt_moving_11::belt_moving</child>
            <axis>
                <xyz>0 1 0</xyz>
                <limit>
                    <lower>0.0</lower>
                    <upper>0.01</upper>
                </limit>
            </axis>
        </joint>
    </model>

    <!-- Workcell factory environment -->
    <model name='workcell'>
      <static>1</static>
      <link name='link'>
        <visual name='visual'>
          <geometry>
            <mesh>
              <uri>model://workcell/meshes/mesh.dae</uri>
            </mesh>
          </geometry>
        </visual>
        <collision name='floor'>
          <pose frame=''>0 0 -0.1 0 -0 0</pose>
          <geometry>
            <box>
              <size>20.1026 20.1026 0.2</size>
            </box>
          </geometry>
          <surface>
            <contact>
              <ode>
                <max_vel>0</max_vel>
                <min_depth>0.001</min_depth>
              </ode>
            </contact>
            <bounce/>
            <friction>
              <torsional>
                <ode/>
              </torsional>
              <ode/>
            </friction>
          </surface>
          <max_contacts>10</max_contacts>
        </collision>
        <collision name='wall1'>
          <pose frame=''>4.13686 -10.0212 3.48855 0 -0 0</pose>
          <geometry>
            <box>
              <size>12.0768 0.72902 6.97771</size>
            </box>
          </geometry>
          <max_contacts>10</max_contacts>
          <surface>
            <contact>
              <ode/>
            </contact>
            <bounce/>
            <friction>
              <torsional>
                <ode/>
              </torsional>
              <ode/>
            </friction>
          </surface>
        </collision>
        <collision name='wall2'>
          <pose frame=''>-6.58151 -8.924 3.48855 0 -0 0</pose>
          <geometry>
            <box>
              <size>10.5921 5.00198 6.97771</size>
            </box>
          </geometry>
          <max_contacts>10</max_contacts>
          <surface>
            <contact>
              <ode/>
            </contact>
            <bounce/>
            <friction>
              <torsional>
                <ode/>
              </torsional>
              <ode/>
            </friction>
          </surface>
        </collision>
        <collision name='wall3'>
          <pose frame=''>-9.25721 0.6135 3.48855 0 -0 0</pose>
          <geometry>
            <box>
              <size>0.72902 15.2908 6.97771</size>
            </box>
          </geometry>
          <max_contacts>10</max_contacts>
          <surface>
            <contact>
              <ode/>
            </contact>
            <bounce/>
            <friction>
              <torsional>
                <ode/>
              </torsional>
              <ode/>
            </friction>
          </surface>
        </collision>
        <collision name='rack1'>
          <pose frame=''>7.35056 1.7443 1.41643 0 -0 0</pose>
          <geometry>
            <box>
              <size>0.84444 1.95581 2.83286</size>
            </box>
          </geometry>
          <max_contacts>10</max_contacts>
          <surface>
            <contact>
              <ode/>
            </contact>
            <bounce/>
            <friction>
              <torsional>
                <ode/>
              </torsional>
              <ode/>
            </friction>
          </surface>
        </collision>
        <collision name='rack2'>
          <pose frame=''>5.36795 1.7443 1.41643 0 -0 0</pose>
          <geometry>
            <box>
              <size>0.84444 1.95581 2.83286</size>
            </box>
          </geometry>
          <max_contacts>10</max_contacts>
          <surface>
            <contact>
              <ode/>
            </contact>
            <bounce/>
            <friction>
              <torsional>
                <ode/>
              </torsional>
              <ode/>
            </friction>
          </surface>
        </collision>
        <collision name='rack3'>
          <pose frame=''>7.00142 -7.6467 1.41643 0 -0 0</pose>
          <geometry>
            <box>
              <size>0.84444 3.91162 2.83286</size>
            </box>
          </geometry>
          <max_contacts>10</max_contacts>
          <surface>
            <contact>
              <ode/>
            </contact>
            <bounce/>
            <friction>
              <torsional>
                <ode/>
              </torsional>
              <ode/>
            </friction>
          </surface>
        </collision>
        <collision name='rack4'>
          <pose frame=''>4.97338 -7.6467 1.41643 0 -0 0</pose>
          <geometry>
            <box>
              <size>0.84444 3.91162 2.83286</size>
            </box>
          </geometry>
          <max_contacts>10</max_contacts>
          <surface>
            <contact>
              <ode/>
            </contact>
            <bounce/>
            <friction>
              <torsional>
                <ode/>
              </torsional>
              <ode/>
            </friction>
          </surface>
        </collision>
        <collision name='rack5'>
          <pose frame=''>2.66949 -7.6467 1.41643 0 -0 0</pose>
          <geometry>
            <box>
              <size>0.84444 3.91162 2.83286</size>
            </box>
          </geometry>
          <max_contacts>10</max_contacts>
          <surface>
            <contact>
              <ode/>
            </contact>
            <bounce/>
            <friction>
              <torsional>
                <ode/>
              </torsional>
              <ode/>
            </friction>
          </surface>
        </collision>
        <collision name='large_pallet1'>
          <pose frame=''>-3.33609 6.31883 1.04257 0 -0 0</pose>
          <geometry>
            <box>
              <size>2.14726 1.79349 2.08514</size>
            </box>
          </geometry>
          <max_contacts>10</max_contacts>
          <surface>
            <contact>
              <ode/>
            </contact>
            <bounce/>
            <friction>
              <torsional>
                <ode/>
              </torsional>
              <ode/>
            </friction>
          </surface>
        </collision>
        <collision name='large_pallet2'>
          <pose frame=''>-5.74492 6.31883 1.04257 0 -0 0</pose>
          <geometry>
            <box>
              <size>2.14726 1.79349 2.08514</size>
            </box>
          </geometry>
          <max_contacts>10</max_contacts>
          <surface>
            <contact>
              <ode/>
            </contact>
            <bounce/>
            <friction>
              <torsional>
                <ode/>
              </torsional>
              <ode/>
            </friction>
          </surface>
        </collision>
        <collision name='large_pallet3'>
          <pose frame=''>-7.55868 1.91644 1.04257 0 -0 0</pose>
          <geometry>
            <box>
              <size>2.14726 1.79432 2.08514</size>
            </box>
          </geometry>
          <max_contacts>10</max_contacts>
          <surface>
            <contact>
              <ode/>
            </contact>
            <bounce/>
            <friction>
              <torsional>
                <ode/>
              </torsional>
              <ode/>
            </friction>
          </surface>
        </collision>
        <collision name='empty_pallet1'>
          <pose frame=''>-5.29667 1.91644 0.1636 0 -0 0</pose>
          <geometry>
            <box>
              <size>2.14726 1.79349 0.3272</size>
            </box>
          </geometry>
          <max_contacts>10</max_contacts>
          <surface>
            <contact>
              <ode/>
            </contact>
            <bounce/>
            <friction>
              <torsional>
                <ode/>
              </torsional>
              <ode/>
            </friction>
          </surface>
        </collision>
        <collision name='box_pallet1'>
          <pose frame=''>-1.09806 6.31883 0.61958 0 -0 0</pose>
          <geometry>
            <box>
              <size>2.14726 1.79349 1.23916</size>
            </box>
          </geometry>
          <max_contacts>10</max_contacts>
          <surface>
            <contact>
              <ode/>
            </contact>
            <bounce/>
            <friction>
              <torsional>
                <ode/>
              </torsional>
              <ode/>
            </friction>
          </surface>
        </collision>
        <!-- 这里是中间传送带 -->
        <collision name='pole1'>
          <pose frame=''>5.02174 -2.39478 3.02208 0 -0 0</pose>
          <geometry>
            <box>
              <size>0.49161 0.49161 6.04415</size>
            </box>
          </geometry>
          <max_contacts>10</max_contacts>
          <surface>
            <contact>
              <ode/>
            </contact>
            <bounce/>
            <friction>
              <torsional>
                <ode/>
              </torsional>
              <ode/>
            </friction>
          </surface>
        </collision>
        <collision name='pole2'>
          <pose frame=''>0.47071 -2.39478 3.02208 0 -0 0</pose>
          <geometry>
            <box>
              <size>0.49161 0.49161 6.04415</size>
            </box>
          </geometry>
          <max_contacts>10</max_contacts>
          <surface>
            <contact>
              <ode/>
            </contact>
            <bounce/>
            <friction>
              <torsional>
                <ode/>
              </torsional>
              <ode/>
            </friction>
          </surface>
        </collision>
        <collision name='pole3'>
          <pose frame=''>-3.93786 -2.39478 3.02208 0 -0 0</pose>
          <geometry>
            <box>
              <size>0.49161 0.49161 6.04415</size>
            </box>
          </geometry>
          <max_contacts>10</max_contacts>
          <surface>
            <contact>
              <ode/>
            </contact>
            <bounce/>
            <friction>
              <torsional>
                <ode/>
              </torsional>
              <ode/>
            </friction>
          </surface>
        </collision>
        <collision name='control_panel'>
          <pose frame=''>2.07015 1.16224 0.561315 0 -0 0</pose>
          <geometry>
            <box>
              <size>0.86733 0.6001 1.12263</size>
            </box>
          </geometry>
          <max_contacts>10</max_contacts>
          <surface>
            <contact>
              <ode/>
            </contact>
            <bounce/>
            <friction>
              <torsional>
                <ode/>
              </torsional>
              <ode/>
            </friction>
          </surface>
        </collision>

        <self_collide>0</self_collide>
        <enable_wind>0</enable_wind>
        <kinematic>0</kinematic>
      </link>
      <pose frame=''>-0.040107 0.052292 0 0 -0 0</pose>
    </model>
    <!-- 图右下方的垃圾桶 * 6 -->
    <model name='workcell_bin'>
      <static>1</static>
      <link name='link'>
        <visual name='visual'>
          <geometry>
            <mesh>
              <uri>model://workcell_bin/meshes/bin.dae</uri>
            </mesh>
          </geometry>
        </visual>
        <collision name='center_collision'>
          <pose frame=''>0 0 0.45 0 -0 0</pose>
          <geometry>
            <box>
              <size>0.6 0.6 0.55</size>
            </box>
          </geometry>
          <max_contacts>10</max_contacts>
          <surface>
            <contact>
              <ode/>
            </contact>
            <bounce/>
            <friction>
              <torsional>
                <ode/>
              </torsional>
              <ode/>
            </friction>
          </surface>
        </collision>
        <visual name='center_visual'>
          <pose frame=''>0 0 0.45 0 -0 0</pose>
          <geometry>
            <box>
              <size>0.6 0.6 0.55</size>
            </box>
          </geometry>
          <material>
            <ambient>0.486275 0.819608 1 1</ambient>
            <diffuse>0.486275 0.819608 1 1</diffuse>
          </material>
        </visual>
        <collision name='base'>
          <pose frame=''>0 0 0.100245 0 -0 0</pose>
          <geometry>
            <box>
              <size>0.66836 0.66836 0.20049</size>
            </box>
          </geometry>
          <max_contacts>10</max_contacts>
          <surface>
            <contact>
              <ode/>
            </contact>
            <bounce/>
            <friction>
              <torsional>
                <ode/>
              </torsional>
              <ode/>
            </friction>
          </surface>
        </collision>
        <collision name='left_wall'>
          <pose frame=''>-0.319 0 0.395445 0 -0 0</pose>
          <geometry>
            <box>
              <size>0.003 0.63803 0.79089</size>
            </box>
          </geometry>
          <max_contacts>10</max_contacts>
          <surface>
            <contact>
              <ode/>
            </contact>
            <bounce/>
            <friction>
              <torsional>
                <ode/>
              </torsional>
              <ode/>
            </friction>
          </surface>
        </collision>
        <collision name='right_wall'>
          <pose frame=''>0.319 0 0.395445 0 -0 0</pose>
          <geometry>
            <box>
              <size>0.003 0.63803 0.79089</size>
            </box>
          </geometry>
          <max_contacts>10</max_contacts>
          <surface>
            <contact>
              <ode/>
            </contact>
            <bounce/>
            <friction>
              <torsional>
                <ode/>
              </torsional>
              <ode/>
            </friction>
          </surface>
        </collision>
        <collision name='front_left_wall'>
          <pose frame=''>-0.25331 0.31899 0.395445 0 -0 0</pose>
          <geometry>
            <box>
              <size>0.13437 0.003 0.79089</size>
            </box>
          </geometry>
          <max_contacts>10</max_contacts>
          <surface>
            <contact>
              <ode/>
            </contact>
            <bounce/>
            <friction>
              <torsional>
                <ode/>
              </torsional>
              <ode/>
            </friction>
          </surface>
        </collision>
        <collision name='front_mid_wall'>
          <pose frame=''>0 0.31899 0.252845 0 -0 0</pose>
          <geometry>
            <box>
              <size>0.37226 0.003 0.50569</size>
            </box>
          </geometry>
          <max_contacts>10</max_contacts>
          <surface>
            <contact>
              <ode/>
            </contact>
            <bounce/>
            <friction>
              <torsional>
                <ode/>
              </torsional>
              <ode/>
            </friction>
          </surface>
        </collision>
        <collision name='front_right_wall'>
          <pose frame=''>0.25331 0.31899 0.395445 0 -0 0</pose>
          <geometry>
            <box>
              <size>0.13437 0.003 0.79089</size>
            </box>
          </geometry>
          <max_contacts>10</max_contacts>
          <surface>
            <contact>
              <ode/>
            </contact>
            <bounce/>
            <friction>
              <torsional>
                <ode/>
              </torsional>
              <ode/>
            </friction>
          </surface>
        </collision>
        <collision name='back_left_wall'>
          <pose frame=''>-0.25331 -0.31899 0.395445 0 -0 0</pose>
          <geometry>
            <box>
              <size>0.13437 0.003 0.79089</size>
            </box>
          </geometry>
          <max_contacts>10</max_contacts>
          <surface>
            <contact>
              <ode/>
            </contact>
            <bounce/>
            <friction>
              <torsional>
                <ode/>
              </torsional>
              <ode/>
            </friction>
          </surface>
        </collision>
        <collision name='back_mid_wall'>
          <pose frame=''>0 -0.31899 0.252845 0 -0 0</pose>
          <geometry>
            <box>
              <size>0.37226 0.003 0.50569</size>
            </box>
          </geometry>
          <max_contacts>10</max_contacts>
          <surface>
            <contact>
              <ode/>
            </contact>
            <bounce/>
            <friction>
              <torsional>
                <ode/>
              </torsional>
              <ode/>
            </friction>
          </surface>
        </collision>
        <collision name='back_right_wall'>
          <pose frame=''>0.25331 -0.31899 0.395445 0 -0 0</pose>
          <geometry>
            <box>
              <size>0.13437 0.003 0.79089</size>
            </box>
          </geometry>
          <max_contacts>10</max_contacts>
          <surface>
            <contact>
              <ode/>
            </contact>
            <bounce/>
            <friction>
              <torsional>
                <ode/>
              </torsional>
              <ode/>
            </friction>
          </surface>
        </collision>
        <self_collide>0</self_collide>
        <enable_wind>0</enable_wind>
        <kinematic>0</kinematic>
      </link>
      <pose frame=''>2.88085 5.68612 0 0 -0 0</pose>
    </model>
    <model name='workcell_bin_clone'>
      <static>1</static>
      <link name='link'>
        <visual name='visual'>
          <geometry>
            <mesh>
              <uri>model://workcell_bin/meshes/bin.dae</uri>
            </mesh>
          </geometry>
        </visual>
        <collision name='center_collision'>
          <pose frame=''>0 0 0.45 0 -0 0</pose>
          <geometry>
            <box>
              <size>0.6 0.6 0.55</size>
            </box>
          </geometry>
          <max_contacts>10</max_contacts>
          <surface>
            <contact>
              <ode/>
            </contact>
            <bounce/>
            <friction>
              <torsional>
                <ode/>
              </torsional>
              <ode/>
            </friction>
          </surface>
        </collision>
        <visual name='center_visual'>
          <pose frame=''>0 0 0.45 0 -0 0</pose>
          <geometry>
            <box>
              <size>0.6 0.6 0.55</size>
            </box>
          </geometry>
          <material>
            <ambient>0.486275 0.819608 1 1</ambient>
            <diffuse>0.486275 0.819608 1 1</diffuse>
          </material>
        </visual>
        <collision name='base'>
          <pose frame=''>0 0 0.100245 0 -0 0</pose>
          <geometry>
            <box>
              <size>0.66836 0.66836 0.20049</size>
            </box>
          </geometry>
          <max_contacts>10</max_contacts>
          <surface>
            <contact>
              <ode/>
            </contact>
            <bounce/>
            <friction>
              <torsional>
                <ode/>
              </torsional>
              <ode/>
            </friction>
          </surface>
        </collision>
        <collision name='left_wall'>
          <pose frame=''>-0.319 0 0.395445 0 -0 0</pose>
          <geometry>
            <box>
              <size>0.003 0.63803 0.79089</size>
            </box>
          </geometry>
          <max_contacts>10</max_contacts>
          <surface>
            <contact>
              <ode/>
            </contact>
            <bounce/>
            <friction>
              <torsional>
                <ode/>
              </torsional>
              <ode/>
            </friction>
          </surface>
        </collision>
        <collision name='right_wall'>
          <pose frame=''>0.319 0 0.395445 0 -0 0</pose>
          <geometry>
            <box>
              <size>0.003 0.63803 0.79089</size>
            </box>
          </geometry>
          <max_contacts>10</max_contacts>
          <surface>
            <contact>
              <ode/>
            </contact>
            <bounce/>
            <friction>
              <torsional>
                <ode/>
              </torsional>
              <ode/>
            </friction>
          </surface>
        </collision>
        <collision name='front_left_wall'>
          <pose frame=''>-0.25331 0.31899 0.395445 0 -0 0</pose>
          <geometry>
            <box>
              <size>0.13437 0.003 0.79089</size>
            </box>
          </geometry>
          <max_contacts>10</max_contacts>
          <surface>
            <contact>
              <ode/>
            </contact>
            <bounce/>
            <friction>
              <torsional>
                <ode/>
              </torsional>
              <ode/>
            </friction>
          </surface>
        </collision>
        <collision name='front_mid_wall'>
          <pose frame=''>0 0.31899 0.252845 0 -0 0</pose>
          <geometry>
            <box>
              <size>0.37226 0.003 0.50569</size>
            </box>
          </geometry>
          <max_contacts>10</max_contacts>
          <surface>
            <contact>
              <ode/>
            </contact>
            <bounce/>
            <friction>
              <torsional>
                <ode/>
              </torsional>
              <ode/>
            </friction>
          </surface>
        </collision>
        <collision name='front_right_wall'>
          <pose frame=''>0.25331 0.31899 0.395445 0 -0 0</pose>
          <geometry>
            <box>
              <size>0.13437 0.003 0.79089</size>
            </box>
          </geometry>
          <max_contacts>10</max_contacts>
          <surface>
            <contact>
              <ode/>
            </contact>
            <bounce/>
            <friction>
              <torsional>
                <ode/>
              </torsional>
              <ode/>
            </friction>
          </surface>
        </collision>
        <collision name='back_left_wall'>
          <pose frame=''>-0.25331 -0.31899 0.395445 0 -0 0</pose>
          <geometry>
            <box>
              <size>0.13437 0.003 0.79089</size>
            </box>
          </geometry>
          <max_contacts>10</max_contacts>
          <surface>
            <contact>
              <ode/>
            </contact>
            <bounce/>
            <friction>
              <torsional>
                <ode/>
              </torsional>
              <ode/>
            </friction>
          </surface>
        </collision>
        <collision name='back_mid_wall'>
          <pose frame=''>0 -0.31899 0.252845 0 -0 0</pose>
          <geometry>
            <box>
              <size>0.37226 0.003 0.50569</size>
            </box>
          </geometry>
          <max_contacts>10</max_contacts>
          <surface>
            <contact>
              <ode/>
            </contact>
            <bounce/>
            <friction>
              <torsional>
                <ode/>
              </torsional>
              <ode/>
            </friction>
          </surface>
        </collision>
        <collision name='back_right_wall'>
          <pose frame=''>0.25331 -0.31899 0.395445 0 -0 0</pose>
          <geometry>
            <box>
              <size>0.13437 0.003 0.79089</size>
            </box>
          </geometry>
          <max_contacts>10</max_contacts>
          <surface>
            <contact>
              <ode/>
            </contact>
            <bounce/>
            <friction>
              <torsional>
                <ode/>
              </torsional>
              <ode/>
            </friction>
          </surface>
        </collision>
        <self_collide>0</self_collide>
        <enable_wind>0</enable_wind>
        <kinematic>0</kinematic>
      </link>
      <pose frame=''>3.8356 5.68259 0 0 -0 0</pose>
    </model>
    <model name='workcell_bin_clone_0'>
      <static>1</static>
      <link name='link'>
        <visual name='visual'>
          <geometry>
            <mesh>
              <uri>model://workcell_bin/meshes/bin.dae</uri>
            </mesh>
          </geometry>
        </visual>
        <collision name='center_collision'>
          <pose frame=''>0 0 0.45 0 -0 0</pose>
          <geometry>
            <box>
              <size>0.6 0.6 0.55</size>
            </box>
          </geometry>
          <max_contacts>10</max_contacts>
          <surface>
            <contact>
              <ode/>
            </contact>
            <bounce/>
            <friction>
              <torsional>
                <ode/>
              </torsional>
              <ode/>
            </friction>
          </surface>
        </collision>
        <visual name='center_visual'>
          <pose frame=''>0 0 0.45 0 -0 0</pose>
          <geometry>
            <box>
              <size>0.6 0.6 0.55</size>
            </box>
          </geometry>
          <material>
            <ambient>0.486275 0.819608 1 1</ambient>
            <diffuse>0.486275 0.819608 1 1</diffuse>
          </material>
        </visual>
        <collision name='base'>
          <pose frame=''>0 0 0.100245 0 -0 0</pose>
          <geometry>
            <box>
              <size>0.66836 0.66836 0.20049</size>
            </box>
          </geometry>
          <max_contacts>10</max_contacts>
          <surface>
            <contact>
              <ode/>
            </contact>
            <bounce/>
            <friction>
              <torsional>
                <ode/>
              </torsional>
              <ode/>
            </friction>
          </surface>
        </collision>
        <collision name='left_wall'>
          <pose frame=''>-0.319 0 0.395445 0 -0 0</pose>
          <geometry>
            <box>
              <size>0.003 0.63803 0.79089</size>
            </box>
          </geometry>
          <max_contacts>10</max_contacts>
          <surface>
            <contact>
              <ode/>
            </contact>
            <bounce/>
            <friction>
              <torsional>
                <ode/>
              </torsional>
              <ode/>
            </friction>
          </surface>
        </collision>
        <collision name='right_wall'>
          <pose frame=''>0.319 0 0.395445 0 -0 0</pose>
          <geometry>
            <box>
              <size>0.003 0.63803 0.79089</size>
            </box>
          </geometry>
          <max_contacts>10</max_contacts>
          <surface>
            <contact>
              <ode/>
            </contact>
            <bounce/>
            <friction>
              <torsional>
                <ode/>
              </torsional>
              <ode/>
            </friction>
          </surface>
        </collision>
        <collision name='front_left_wall'>
          <pose frame=''>-0.25331 0.31899 0.395445 0 -0 0</pose>
          <geometry>
            <box>
              <size>0.13437 0.003 0.79089</size>
            </box>
          </geometry>
          <max_contacts>10</max_contacts>
          <surface>
            <contact>
              <ode/>
            </contact>
            <bounce/>
            <friction>
              <torsional>
                <ode/>
              </torsional>
              <ode/>
            </friction>
          </surface>
        </collision>
        <collision name='front_mid_wall'>
          <pose frame=''>0 0.31899 0.252845 0 -0 0</pose>
          <geometry>
            <box>
              <size>0.37226 0.003 0.50569</size>
            </box>
          </geometry>
          <max_contacts>10</max_contacts>
          <surface>
            <contact>
              <ode/>
            </contact>
            <bounce/>
            <friction>
              <torsional>
                <ode/>
              </torsional>
              <ode/>
            </friction>
          </surface>
        </collision>
        <collision name='front_right_wall'>
          <pose frame=''>0.25331 0.31899 0.395445 0 -0 0</pose>
          <geometry>
            <box>
              <size>0.13437 0.003 0.79089</size>
            </box>
          </geometry>
          <max_contacts>10</max_contacts>
          <surface>
            <contact>
              <ode/>
            </contact>
            <bounce/>
            <friction>
              <torsional>
                <ode/>
              </torsional>
              <ode/>
            </friction>
          </surface>
        </collision>
        <collision name='back_left_wall'>
          <pose frame=''>-0.25331 -0.31899 0.395445 0 -0 0</pose>
          <geometry>
            <box>
              <size>0.13437 0.003 0.79089</size>
            </box>
          </geometry>
          <max_contacts>10</max_contacts>
          <surface>
            <contact>
              <ode/>
            </contact>
            <bounce/>
            <friction>
              <torsional>
                <ode/>
              </torsional>
              <ode/>
            </friction>
          </surface>
        </collision>
        <collision name='back_mid_wall'>
          <pose frame=''>0 -0.31899 0.252845 0 -0 0</pose>
          <geometry>
            <box>
              <size>0.37226 0.003 0.50569</size>
            </box>
          </geometry>
          <max_contacts>10</max_contacts>
          <surface>
            <contact>
              <ode/>
            </contact>
            <bounce/>
            <friction>
              <torsional>
                <ode/>
              </torsional>
              <ode/>
            </friction>
          </surface>
        </collision>
        <collision name='back_right_wall'>
          <pose frame=''>0.25331 -0.31899 0.395445 0 -0 0</pose>
          <geometry>
            <box>
              <size>0.13437 0.003 0.79089</size>
            </box>
          </geometry>
          <max_contacts>10</max_contacts>
          <surface>
            <contact>
              <ode/>
            </contact>
            <bounce/>
            <friction>
              <torsional>
                <ode/>
              </torsional>
              <ode/>
            </friction>
          </surface>
        </collision>
        <self_collide>0</self_collide>
        <enable_wind>0</enable_wind>
        <kinematic>0</kinematic>
      </link>
      <pose frame=''>4.95299 5.6442 0 0 -0 0</pose>
    </model>
    <model name='workcell_bin_clone_1'> 
      <static>1</static>
      <link name='link'>
        <visual name='visual'>
          <geometry>
            <mesh>
              <uri>model://workcell_bin/meshes/bin.dae</uri>
            </mesh>
          </geometry>
        </visual>
        <collision name='center_collision'>
          <pose frame=''>0 0 0.45 0 -0 0</pose>
          <geometry>
            <box>
              <size>0.6 0.6 0.55</size>
            </box>
          </geometry>
          <max_contacts>10</max_contacts>
          <surface>
            <contact>
              <ode/>
            </contact>
            <bounce/>
            <friction>
              <torsional>
                <ode/>
              </torsional>
              <ode/>
            </friction>
          </surface>
        </collision>
        <visual name='center_visual'>
          <pose frame=''>0 0 0.45 0 -0 0</pose>
          <geometry>
            <box>
              <size>0.6 0.6 0.55</size>
            </box>
          </geometry>
          <material>
            <ambient>0.486275 0.819608 1 1</ambient>
            <diffuse>0.486275 0.819608 1 1</diffuse>
          </material>
        </visual>
        <collision name='base'>
          <pose frame=''>0 0 0.100245 0 -0 0</pose>
          <geometry>
            <box>
              <size>0.66836 0.66836 0.20049</size>
            </box>
          </geometry>
          <max_contacts>10</max_contacts>
          <surface>
            <contact>
              <ode/>
            </contact>
            <bounce/>
            <friction>
              <torsional>
                <ode/>
              </torsional>
              <ode/>
            </friction>
          </surface>
        </collision>
        <collision name='left_wall'>
          <pose frame=''>-0.319 0 0.395445 0 -0 0</pose>
          <geometry>
            <box>
              <size>0.003 0.63803 0.79089</size>
            </box>
          </geometry>
          <max_contacts>10</max_contacts>
          <surface>
            <contact>
              <ode/>
            </contact>
            <bounce/>
            <friction>
              <torsional>
                <ode/>
              </torsional>
              <ode/>
            </friction>
          </surface>
        </collision>
        <collision name='right_wall'>
          <pose frame=''>0.319 0 0.395445 0 -0 0</pose>
          <geometry>
            <box>
              <size>0.003 0.63803 0.79089</size>
            </box>
          </geometry>
          <max_contacts>10</max_contacts>
          <surface>
            <contact>
              <ode/>
            </contact>
            <bounce/>
            <friction>
              <torsional>
                <ode/>
              </torsional>
              <ode/>
            </friction>
          </surface>
        </collision>
        <collision name='front_left_wall'>
          <pose frame=''>-0.25331 0.31899 0.395445 0 -0 0</pose>
          <geometry>
            <box>
              <size>0.13437 0.003 0.79089</size>
            </box>
          </geometry>
          <max_contacts>10</max_contacts>
          <surface>
            <contact>
              <ode/>
            </contact>
            <bounce/>
            <friction>
              <torsional>
                <ode/>
              </torsional>
              <ode/>
            </friction>
          </surface>
        </collision>
        <collision name='front_mid_wall'>
          <pose frame=''>0 0.31899 0.252845 0 -0 0</pose>
          <geometry>
            <box>
              <size>0.37226 0.003 0.50569</size>
            </box>
          </geometry>
          <max_contacts>10</max_contacts>
          <surface>
            <contact>
              <ode/>
            </contact>
            <bounce/>
            <friction>
              <torsional>
                <ode/>
              </torsional>
              <ode/>
            </friction>
          </surface>
        </collision>
        <collision name='front_right_wall'>
          <pose frame=''>0.25331 0.31899 0.395445 0 -0 0</pose>
          <geometry>
            <box>
              <size>0.13437 0.003 0.79089</size>
            </box>
          </geometry>
          <max_contacts>10</max_contacts>
          <surface>
            <contact>
              <ode/>
            </contact>
            <bounce/>
            <friction>
              <torsional>
                <ode/>
              </torsional>
              <ode/>
            </friction>
          </surface>
        </collision>
        <collision name='back_left_wall'>
          <pose frame=''>-0.25331 -0.31899 0.395445 0 -0 0</pose>
          <geometry>
            <box>
              <size>0.13437 0.003 0.79089</size>
            </box>
          </geometry>
          <max_contacts>10</max_contacts>
          <surface>
            <contact>
              <ode/>
            </contact>
            <bounce/>
            <friction>
              <torsional>
                <ode/>
              </torsional>
              <ode/>
            </friction>
          </surface>
        </collision>
        <collision name='back_mid_wall'>
          <pose frame=''>0 -0.31899 0.252845 0 -0 0</pose>
          <geometry>
            <box>
              <size>0.37226 0.003 0.50569</size>
            </box>
          </geometry>
          <max_contacts>10</max_contacts>
          <surface>
            <contact>
              <ode/>
            </contact>
            <bounce/>
            <friction>
              <torsional>
                <ode/>
              </torsional>
              <ode/>
            </friction>
          </surface>
        </collision>
        <collision name='back_right_wall'>
          <pose frame=''>0.25331 -0.31899 0.395445 0 -0 0</pose>
          <geometry>
            <box>
              <size>0.13437 0.003 0.79089</size>
            </box>
          </geometry>
          <max_contacts>10</max_contacts>
          <surface>
            <contact>
              <ode/>
            </contact>
            <bounce/>
            <friction>
              <torsional>
                <ode/>
              </torsional>
              <ode/>
            </friction>
          </surface>
        </collision>
        <self_collide>0</self_collide>
        <enable_wind>0</enable_wind>
        <kinematic>0</kinematic>
      </link>
      <pose frame=''>5.85776 5.64162 0 0 -0 0</pose>
    </model>
    <model name='workcell_bin_clone_2'>
      <static>1</static>
      <link name='link'>
        <visual name='visual'>
          <geometry>
            <mesh>
              <uri>model://workcell_bin/meshes/bin.dae</uri>
            </mesh>
          </geometry>
        </visual>
        <collision name='center_collision'>
          <pose frame=''>0 0 0.45 0 -0 0</pose>
          <geometry>
            <box>
              <size>0.6 0.6 0.55</size>
            </box>
          </geometry>
          <max_contacts>10</max_contacts>
          <surface>
            <contact>
              <ode/>
            </contact>
            <bounce/>
            <friction>
              <torsional>
                <ode/>
              </torsional>
              <ode/>
            </friction>
          </surface>
        </collision>
        <visual name='center_visual'>
          <pose frame=''>0 0 0.45 0 -0 0</pose>
          <geometry>
            <box>
              <size>0.6 0.6 0.55</size>
            </box>
          </geometry>
          <material>
            <ambient>0.486275 0.819608 1 1</ambient>
            <diffuse>0.486275 0.819608 1 1</diffuse>
          </material>
        </visual>
        <collision name='base'>
          <pose frame=''>0 0 0.100245 0 -0 0</pose>
          <geometry>
            <box>
              <size>0.66836 0.66836 0.20049</size>
            </box>
          </geometry>
          <max_contacts>10</max_contacts>
          <surface>
            <contact>
              <ode/>
            </contact>
            <bounce/>
            <friction>
              <torsional>
                <ode/>
              </torsional>
              <ode/>
            </friction>
          </surface>
        </collision>
        <collision name='left_wall'>
          <pose frame=''>-0.319 0 0.395445 0 -0 0</pose>
          <geometry>
            <box>
              <size>0.003 0.63803 0.79089</size>
            </box>
          </geometry>
          <max_contacts>10</max_contacts>
          <surface>
            <contact>
              <ode/>
            </contact>
            <bounce/>
            <friction>
              <torsional>
                <ode/>
              </torsional>
              <ode/>
            </friction>
          </surface>
        </collision>
        <collision name='right_wall'>
          <pose frame=''>0.319 0 0.395445 0 -0 0</pose>
          <geometry>
            <box>
              <size>0.003 0.63803 0.79089</size>
            </box>
          </geometry>
          <max_contacts>10</max_contacts>
          <surface>
            <contact>
              <ode/>
            </contact>
            <bounce/>
            <friction>
              <torsional>
                <ode/>
              </torsional>
              <ode/>
            </friction>
          </surface>
        </collision>
        <collision name='front_left_wall'>
          <pose frame=''>-0.25331 0.31899 0.395445 0 -0 0</pose>
          <geometry>
            <box>
              <size>0.13437 0.003 0.79089</size>
            </box>
          </geometry>
          <max_contacts>10</max_contacts>
          <surface>
            <contact>
              <ode/>
            </contact>
            <bounce/>
            <friction>
              <torsional>
                <ode/>
              </torsional>
              <ode/>
            </friction>
          </surface>
        </collision>
        <collision name='front_mid_wall'>
          <pose frame=''>0 0.31899 0.252845 0 -0 0</pose>
          <geometry>
            <box>
              <size>0.37226 0.003 0.50569</size>
            </box>
          </geometry>
          <max_contacts>10</max_contacts>
          <surface>
            <contact>
              <ode/>
            </contact>
            <bounce/>
            <friction>
              <torsional>
                <ode/>
              </torsional>
              <ode/>
            </friction>
          </surface>
        </collision>
        <collision name='front_right_wall'>
          <pose frame=''>0.25331 0.31899 0.395445 0 -0 0</pose>
          <geometry>
            <box>
              <size>0.13437 0.003 0.79089</size>
            </box>
          </geometry>
          <max_contacts>10</max_contacts>
          <surface>
            <contact>
              <ode/>
            </contact>
            <bounce/>
            <friction>
              <torsional>
                <ode/>
              </torsional>
              <ode/>
            </friction>
          </surface>
        </collision>
        <collision name='back_left_wall'>
          <pose frame=''>-0.25331 -0.31899 0.395445 0 -0 0</pose>
          <geometry>
            <box>
              <size>0.13437 0.003 0.79089</size>
            </box>
          </geometry>
          <max_contacts>10</max_contacts>
          <surface>
            <contact>
              <ode/>
            </contact>
            <bounce/>
            <friction>
              <torsional>
                <ode/>
              </torsional>
              <ode/>
            </friction>
          </surface>
        </collision>
        <collision name='back_mid_wall'>
          <pose frame=''>0 -0.31899 0.252845 0 -0 0</pose>
          <geometry>
            <box>
              <size>0.37226 0.003 0.50569</size>
            </box>
          </geometry>
          <max_contacts>10</max_contacts>
          <surface>
            <contact>
              <ode/>
            </contact>
            <bounce/>
            <friction>
              <torsional>
                <ode/>
              </torsional>
              <ode/>
            </friction>
          </surface>
        </collision>
        <collision name='back_right_wall'>
          <pose frame=''>0.25331 -0.31899 0.395445 0 -0 0</pose>
          <geometry>
            <box>
              <size>0.13437 0.003 0.79089</size>
            </box>
          </geometry>
          <max_contacts>10</max_contacts>
          <surface>
            <contact>
              <ode/>
            </contact>
            <bounce/>
            <friction>
              <torsional>
                <ode/>
              </torsional>
              <ode/>
            </friction>
          </surface>
        </collision>
        <self_collide>0</self_collide>
        <enable_wind>0</enable_wind>
        <kinematic>0</kinematic>
      </link>
      <pose frame=''>7.00972 5.66323 0 0 -0 0</pose>
    </model>
    <model name='workcell_bin_clone_3'>
      <static>1</static>
      <link name='link'>
        <visual name='visual'>
          <geometry>
            <mesh>
              <uri>model://workcell_bin/meshes/bin.dae</uri>
            </mesh>
          </geometry>
        </visual>
        <collision name='center_collision'>
          <pose frame=''>0 0 0.45 0 -0 0</pose>
          <geometry>
            <box>
              <size>0.6 0.6 0.55</size>
            </box>
          </geometry>
          <max_contacts>10</max_contacts>
          <surface>
            <contact>
              <ode/>
            </contact>
            <bounce/>
            <friction>
              <torsional>
                <ode/>
              </torsional>
              <ode/>
            </friction>
          </surface>
        </collision>
        <visual name='center_visual'>
          <pose frame=''>0 0 0.45 0 -0 0</pose>
          <geometry>
            <box>
              <size>0.6 0.6 0.55</size>
            </box>
          </geometry>
          <material>
            <ambient>0.486275 0.819608 1 1</ambient>
            <diffuse>0.486275 0.819608 1 1</diffuse>
          </material>
        </visual>
        <collision name='base'>
          <pose frame=''>0 0 0.100245 0 -0 0</pose>
          <geometry>
            <box>
              <size>0.66836 0.66836 0.20049</size>
            </box>
          </geometry>
          <max_contacts>10</max_contacts>
          <surface>
            <contact>
              <ode/>
            </contact>
            <bounce/>
            <friction>
              <torsional>
                <ode/>
              </torsional>
              <ode/>
            </friction>
          </surface>
        </collision>
        <collision name='left_wall'>
          <pose frame=''>-0.319 0 0.395445 0 -0 0</pose>
          <geometry>
            <box>
              <size>0.003 0.63803 0.79089</size>
            </box>
          </geometry>
          <max_contacts>10</max_contacts>
          <surface>
            <contact>
              <ode/>
            </contact>
            <bounce/>
            <friction>
              <torsional>
                <ode/>
              </torsional>
              <ode/>
            </friction>
          </surface>
        </collision>
        <collision name='right_wall'>
          <pose frame=''>0.319 0 0.395445 0 -0 0</pose>
          <geometry>
            <box>
              <size>0.003 0.63803 0.79089</size>
            </box>
          </geometry>
          <max_contacts>10</max_contacts>
          <surface>
            <contact>
              <ode/>
            </contact>
            <bounce/>
            <friction>
              <torsional>
                <ode/>
              </torsional>
              <ode/>
            </friction>
          </surface>
        </collision>
        <collision name='front_left_wall'>
          <pose frame=''>-0.25331 0.31899 0.395445 0 -0 0</pose>
          <geometry>
            <box>
              <size>0.13437 0.003 0.79089</size>
            </box>
          </geometry>
          <max_contacts>10</max_contacts>
          <surface>
            <contact>
              <ode/>
            </contact>
            <bounce/>
            <friction>
              <torsional>
                <ode/>
              </torsional>
              <ode/>
            </friction>
          </surface>
        </collision>
        <collision name='front_mid_wall'>
          <pose frame=''>0 0.31899 0.252845 0 -0 0</pose>
          <geometry>
            <box>
              <size>0.37226 0.003 0.50569</size>
            </box>
          </geometry>
          <max_contacts>10</max_contacts>
          <surface>
            <contact>
              <ode/>
            </contact>
            <bounce/>
            <friction>
              <torsional>
                <ode/>
              </torsional>
              <ode/>
            </friction>
          </surface>
        </collision>
        <collision name='front_right_wall'>
          <pose frame=''>0.25331 0.31899 0.395445 0 -0 0</pose>
          <geometry>
            <box>
              <size>0.13437 0.003 0.79089</size>
            </box>
          </geometry>
          <max_contacts>10</max_contacts>
          <surface>
            <contact>
              <ode/>
            </contact>
            <bounce/>
            <friction>
              <torsional>
                <ode/>
              </torsional>
              <ode/>
            </friction>
          </surface>
        </collision>
        <collision name='back_left_wall'>
          <pose frame=''>-0.25331 -0.31899 0.395445 0 -0 0</pose>
          <geometry>
            <box>
              <size>0.13437 0.003 0.79089</size>
            </box>
          </geometry>
          <max_contacts>10</max_contacts>
          <surface>
            <contact>
              <ode/>
            </contact>
            <bounce/>
            <friction>
              <torsional>
                <ode/>
              </torsional>
              <ode/>
            </friction>
          </surface>
        </collision>
        <collision name='back_mid_wall'>
          <pose frame=''>0 -0.31899 0.252845 0 -0 0</pose>
          <geometry>
            <box>
              <size>0.37226 0.003 0.50569</size>
            </box>
          </geometry>
          <max_contacts>10</max_contacts>
          <surface>
            <contact>
              <ode/>
            </contact>
            <bounce/>
            <friction>
              <torsional>
                <ode/>
              </torsional>
              <ode/>
            </friction>
          </surface>
        </collision>
        <collision name='back_right_wall'>
          <pose frame=''>0.25331 -0.31899 0.395445 0 -0 0</pose>
          <geometry>
            <box>
              <size>0.13437 0.003 0.79089</size>
            </box>
          </geometry>
          <max_contacts>10</max_contacts>
          <surface>
            <contact>
              <ode/>
            </contact>
            <bounce/>
            <friction>
              <torsional>
                <ode/>
              </torsional>
              <ode/>
            </friction>
          </surface>
        </collision>
        <self_collide>0</self_collide>
        <enable_wind>0</enable_wind>
        <kinematic>0</kinematic>
      </link>
      <pose frame=''>8.07235 5.67521 0 0 -0 0</pose>
    </model>
    <state world_name='default'>
      <sim_time>174 885000000</sim_time>
      <real_time>175 813785601</real_time>
      <wall_time>1587523933 130462287</wall_time>
      <iterations>174885</iterations>
      <model name='ground_plane'>
        <pose frame=''>0 0 0 0 -0 0</pose>
        <scale>1 1 1</scale>
        <link name='link'>
          <pose frame=''>0 0 0 0 -0 0</pose>
          <velocity>0 0 0 0 -0 0</velocity>
          <acceleration>0 0 0 0 -0 0</acceleration>
          <wrench>0 0 0 0 -0 0</wrench>
        </link>
      </model>

      <model name='workcell'>
        <pose frame=''>-0.040107 0.052292 0 0 -0 0</pose>
        <scale>1 1 1</scale>
        <link name='link'>
          <pose frame=''>-0.040107 0.052292 0 0 -0 0</pose>
          <velocity>0 0 0 0 -0 0</velocity>
          <acceleration>0 0 0 0 -0 0</acceleration>
          <wrench>0 0 0 0 -0 0</wrench>
        </link>
      </model>
      <model name='workcell_bin'>
        <pose frame=''>3 6 0 0 -0 0</pose>
        <scale>1 1 1</scale>
        <link name='link'>
          <pose frame=''>3 6 0 0 -0 0</pose>
          <velocity>0 0 0 0 -0 0</velocity>
          <acceleration>0 0 0 0 -0 0</acceleration>
          <wrench>0 0 0 0 -0 0</wrench>
        </link>
      </model>
      <model name='workcell_bin_clone'>
        <pose frame=''>4 6 0 0 -0 0</pose>
        <scale>1 1 1</scale>
        <link name='link'>
          <pose frame=''>4 6 0 0 -0 0</pose>
          <velocity>0 0 0 0 -0 0</velocity>
          <acceleration>0 0 0 0 -0 0</acceleration>
          <wrench>0 0 0 0 -0 0</wrench>
        </link>
      </model>
      <model name='workcell_bin_clone_0'>
        <pose frame=''>5 6 0 0 -0 0</pose>
        <scale>1 1 1</scale>
        <link name='link'>
          <pose frame=''>5 6 0 0 -0 0</pose>
          <velocity>0 0 0 0 -0 0</velocity>
          <acceleration>0 0 0 0 -0 0</acceleration>
          <wrench>0 0 0 0 -0 0</wrench>
        </link>
      </model>
      <model name='workcell_bin_clone_1'>
        <pose frame=''>6 6 0 0 -0 0</pose>
        <scale>1 1 1</scale>
        <link name='link'>
          <pose frame=''>6 6 0 0 -0 0</pose>
          <velocity>0 0 0 0 -0 0</velocity>
          <acceleration>0 0 0 0 -0 0</acceleration>
          <wrench>0 0 0 0 -0 0</wrench>
        </link>
      </model>
      <model name='workcell_bin_clone_2'>
        <pose frame=''>7.0 6 0 0 -0 0</pose>
        <scale>1 1 1</scale>
        <link name='link'>
          <pose frame=''>7 6 0 0 -0 0</pose>
          <velocity>0 0 0 0 -0 0</velocity>
          <acceleration>0 0 0 0 -0 0</acceleration>
          <wrench>0 0 0 0 -0 0</wrench>
        </link>
      </model>
      <!-- <model name='workcell_bin_clone_3'>
        <pose frame=''>8 6 0 0 -0 0</pose>
        <scale>1 1 1</scale>
        <link name='link'>
          <pose frame=''>8 6 0 0 -0 0</pose>
          <velocity>0 0 0 0 -0 0</velocity>
          <acceleration>0 0 0 0 -0 0</acceleration>
          <wrench>0 0 0 0 -0 0</wrench>
        </link>
      </model> -->

      <!-- Include the conveyor belt-->
      <light name='sun'>
        <pose frame=''>0 0 10 0 -0 0</pose>
      </light>
    </state>
   




  </world>
</sdf>